[2025-09-03T00:24:55.622+0000] {taskinstance.py:1083} INFO - Dependencies all met for <TaskInstance: institution_detail_data_quality_pipeline.validate manual__2025-09-03T00:24:49.989198+00:00 [queued]>
[2025-09-03T00:24:55.628+0000] {taskinstance.py:1083} INFO - Dependencies all met for <TaskInstance: institution_detail_data_quality_pipeline.validate manual__2025-09-03T00:24:49.989198+00:00 [queued]>
[2025-09-03T00:24:55.628+0000] {taskinstance.py:1279} INFO - 
--------------------------------------------------------------------------------
[2025-09-03T00:24:55.628+0000] {taskinstance.py:1280} INFO - Starting attempt 1 of 1
[2025-09-03T00:24:55.628+0000] {taskinstance.py:1281} INFO - 
--------------------------------------------------------------------------------
[2025-09-03T00:24:55.637+0000] {taskinstance.py:1300} INFO - Executing <Task(BranchPythonOperator): validate> on 2025-09-03 00:24:49.989198+00:00
[2025-09-03T00:24:55.640+0000] {standard_task_runner.py:55} INFO - Started process 16249 to run task
[2025-09-03T00:24:55.642+0000] {standard_task_runner.py:82} INFO - Running: ['***', 'tasks', 'run', 'institution_detail_data_quality_pipeline', 'validate', 'manual__2025-09-03T00:24:49.989198+00:00', '--job-id', '97', '--raw', '--subdir', 'DAGS_FOLDER/dag_dataquality.py', '--cfg-path', '/tmp/tmpi_yc7dd8']
[2025-09-03T00:24:55.643+0000] {standard_task_runner.py:83} INFO - Job 97: Subtask validate
[2025-09-03T00:24:55.655+0000] {logging_mixin.py:137} WARNING - /usr/local/lib/python3.9/site-packages/***/settings.py:249 DeprecationWarning: The sql_alchemy_conn option in [core] has been moved to the sql_alchemy_conn option in [database] - the old setting has been used, but please update your config.
[2025-09-03T00:24:55.687+0000] {task_command.py:388} INFO - Running <TaskInstance: institution_detail_data_quality_pipeline.validate manual__2025-09-03T00:24:49.989198+00:00 [running]> on host f321ea8b8484
[2025-09-03T00:24:55.736+0000] {taskinstance.py:1507} INFO - Exporting the following env vars:
AIRFLOW_CTX_DAG_OWNER=Klaus_Rezende
AIRFLOW_CTX_DAG_ID=institution_detail_data_quality_pipeline
AIRFLOW_CTX_TASK_ID=validate
AIRFLOW_CTX_EXECUTION_DATE=2025-09-03T00:24:49.989198+00:00
AIRFLOW_CTX_TRY_NUMBER=1
AIRFLOW_CTX_DAG_RUN_ID=manual__2025-09-03T00:24:49.989198+00:00
[2025-09-03T00:24:55.737+0000] {taskinstance.py:1768} ERROR - Task failed with exception
Traceback (most recent call last):
  File "/usr/local/lib/python3.9/site-packages/airflow/operators/python.py", line 210, in execute
    branch = super().execute(context)
  File "/usr/local/lib/python3.9/site-packages/airflow/operators/python.py", line 175, in execute
    return_value = self.execute_callable()
  File "/usr/local/lib/python3.9/site-packages/airflow/operators/python.py", line 192, in execute_callable
    return self.python_callable(*self.op_args, **self.op_kwargs)
  File "/opt/airflow/dags/dag_dataquality.py", line 22, in validate_percentage
    with open('/opt/airflow/scripts/validation_results.txt', 'r') as file:
FileNotFoundError: [Errno 2] No such file or directory: '/opt/airflow/scripts/validation_results.txt'
[2025-09-03T00:24:55.744+0000] {taskinstance.py:1318} INFO - Marking task as FAILED. dag_id=institution_detail_data_quality_pipeline, task_id=validate, execution_date=20250903T002449, start_date=20250903T002455, end_date=20250903T002455
[2025-09-03T00:24:55.753+0000] {standard_task_runner.py:100} ERROR - Failed to execute job 97 for task validate ([Errno 2] No such file or directory: '/opt/airflow/scripts/validation_results.txt'; 16249)
[2025-09-03T00:24:55.774+0000] {local_task_job.py:208} INFO - Task exited with return code 1
[2025-09-03T00:24:55.794+0000] {taskinstance.py:2578} INFO - 0 downstream tasks scheduled from follow-on schedule check
