[2025-09-03T02:28:24.681+0000] {taskinstance.py:1083} INFO - Dependencies all met for <TaskInstance: institution_detail_data_quality_pipeline.invalid manual__2025-09-03T02:28:17.678938+00:00 [queued]>
[2025-09-03T02:28:24.688+0000] {taskinstance.py:1083} INFO - Dependencies all met for <TaskInstance: institution_detail_data_quality_pipeline.invalid manual__2025-09-03T02:28:17.678938+00:00 [queued]>
[2025-09-03T02:28:24.688+0000] {taskinstance.py:1279} INFO - 
--------------------------------------------------------------------------------
[2025-09-03T02:28:24.688+0000] {taskinstance.py:1280} INFO - Starting attempt 1 of 1
[2025-09-03T02:28:24.688+0000] {taskinstance.py:1281} INFO - 
--------------------------------------------------------------------------------
[2025-09-03T02:28:24.695+0000] {taskinstance.py:1300} INFO - Executing <Task(PythonOperator): invalid> on 2025-09-03 02:28:17.678938+00:00
[2025-09-03T02:28:24.698+0000] {standard_task_runner.py:55} INFO - Started process 2876 to run task
[2025-09-03T02:28:24.700+0000] {standard_task_runner.py:82} INFO - Running: ['***', 'tasks', 'run', 'institution_detail_data_quality_pipeline', 'invalid', 'manual__2025-09-03T02:28:17.678938+00:00', '--job-id', '62', '--raw', '--subdir', 'DAGS_FOLDER/dag_dataquality.py', '--cfg-path', '/tmp/tmp3mknb_xu']
[2025-09-03T02:28:24.701+0000] {standard_task_runner.py:83} INFO - Job 62: Subtask invalid
[2025-09-03T02:28:24.711+0000] {logging_mixin.py:137} WARNING - /usr/local/lib/python3.9/site-packages/***/settings.py:249 DeprecationWarning: The sql_alchemy_conn option in [core] has been moved to the sql_alchemy_conn option in [database] - the old setting has been used, but please update your config.
[2025-09-03T02:28:24.744+0000] {task_command.py:388} INFO - Running <TaskInstance: institution_detail_data_quality_pipeline.invalid manual__2025-09-03T02:28:17.678938+00:00 [running]> on host 72c28e8237fc
[2025-09-03T02:28:24.788+0000] {taskinstance.py:1507} INFO - Exporting the following env vars:
AIRFLOW_CTX_DAG_OWNER=Klaus_Rezende
AIRFLOW_CTX_DAG_ID=institution_detail_data_quality_pipeline
AIRFLOW_CTX_TASK_ID=invalid
AIRFLOW_CTX_EXECUTION_DATE=2025-09-03T02:28:17.678938+00:00
AIRFLOW_CTX_TRY_NUMBER=1
AIRFLOW_CTX_DAG_RUN_ID=manual__2025-09-03T02:28:17.678938+00:00
[2025-09-03T02:28:25.127+0000] {taskinstance.py:1768} ERROR - Task failed with exception
Traceback (most recent call last):
  File "/usr/local/lib/python3.9/site-packages/airflow/operators/python.py", line 175, in execute
    return_value = self.execute_callable()
  File "/usr/local/lib/python3.9/site-packages/airflow/operators/python.py", line 192, in execute_callable
    return self.python_callable(*self.op_args, **self.op_kwargs)
  File "/opt/airflow/dags/dag_dataquality.py", line 40, in error
    raise Exception("Data Quality validation failed...")
Exception: Data Quality validation failed...
[2025-09-03T02:28:25.133+0000] {taskinstance.py:1318} INFO - Marking task as FAILED. dag_id=institution_detail_data_quality_pipeline, task_id=invalid, execution_date=20250903T022817, start_date=20250903T022824, end_date=20250903T022825
[2025-09-03T02:28:25.140+0000] {standard_task_runner.py:100} ERROR - Failed to execute job 62 for task invalid (Data Quality validation failed...; 2876)
[2025-09-03T02:28:25.152+0000] {local_task_job.py:208} INFO - Task exited with return code 1
[2025-09-03T02:28:25.165+0000] {taskinstance.py:2578} INFO - 0 downstream tasks scheduled from follow-on schedule check
