[2025-09-03T04:40:14.540+0000] {taskinstance.py:1083} INFO - Dependencies all met for <TaskInstance: institution_detail_data_quality_pipeline.invalid manual__2025-09-03T04:40:07.940319+00:00 [queued]>
[2025-09-03T04:40:14.546+0000] {taskinstance.py:1083} INFO - Dependencies all met for <TaskInstance: institution_detail_data_quality_pipeline.invalid manual__2025-09-03T04:40:07.940319+00:00 [queued]>
[2025-09-03T04:40:14.546+0000] {taskinstance.py:1279} INFO - 
--------------------------------------------------------------------------------
[2025-09-03T04:40:14.546+0000] {taskinstance.py:1280} INFO - Starting attempt 1 of 1
[2025-09-03T04:40:14.546+0000] {taskinstance.py:1281} INFO - 
--------------------------------------------------------------------------------
[2025-09-03T04:40:14.555+0000] {taskinstance.py:1300} INFO - Executing <Task(PythonOperator): invalid> on 2025-09-03 04:40:07.940319+00:00
[2025-09-03T04:40:14.558+0000] {standard_task_runner.py:55} INFO - Started process 1935 to run task
[2025-09-03T04:40:14.560+0000] {standard_task_runner.py:82} INFO - Running: ['***', 'tasks', 'run', 'institution_detail_data_quality_pipeline', 'invalid', 'manual__2025-09-03T04:40:07.940319+00:00', '--job-id', '12', '--raw', '--subdir', 'DAGS_FOLDER/dag_dataquality.py', '--cfg-path', '/tmp/tmpti1osx9j']
[2025-09-03T04:40:14.561+0000] {standard_task_runner.py:83} INFO - Job 12: Subtask invalid
[2025-09-03T04:40:14.572+0000] {logging_mixin.py:137} WARNING - /usr/local/lib/python3.9/site-packages/***/settings.py:249 DeprecationWarning: The sql_alchemy_conn option in [core] has been moved to the sql_alchemy_conn option in [database] - the old setting has been used, but please update your config.
[2025-09-03T04:40:14.601+0000] {task_command.py:388} INFO - Running <TaskInstance: institution_detail_data_quality_pipeline.invalid manual__2025-09-03T04:40:07.940319+00:00 [running]> on host 56e79e5a4e8c
[2025-09-03T04:40:14.643+0000] {taskinstance.py:1507} INFO - Exporting the following env vars:
AIRFLOW_CTX_DAG_OWNER=Klaus_Rezende
AIRFLOW_CTX_DAG_ID=institution_detail_data_quality_pipeline
AIRFLOW_CTX_TASK_ID=invalid
AIRFLOW_CTX_EXECUTION_DATE=2025-09-03T04:40:07.940319+00:00
AIRFLOW_CTX_TRY_NUMBER=1
AIRFLOW_CTX_DAG_RUN_ID=manual__2025-09-03T04:40:07.940319+00:00
[2025-09-03T04:40:15.001+0000] {taskinstance.py:1768} ERROR - Task failed with exception
Traceback (most recent call last):
  File "/usr/local/lib/python3.9/site-packages/airflow/operators/python.py", line 175, in execute
    return_value = self.execute_callable()
  File "/usr/local/lib/python3.9/site-packages/airflow/operators/python.py", line 192, in execute_callable
    return self.python_callable(*self.op_args, **self.op_kwargs)
  File "/opt/airflow/dags/dag_dataquality.py", line 40, in error
    raise Exception("Data Quality validation failed...")
Exception: Data Quality validation failed...
[2025-09-03T04:40:15.008+0000] {taskinstance.py:1318} INFO - Marking task as FAILED. dag_id=institution_detail_data_quality_pipeline, task_id=invalid, execution_date=20250903T044007, start_date=20250903T044014, end_date=20250903T044015
[2025-09-03T04:40:15.018+0000] {standard_task_runner.py:100} ERROR - Failed to execute job 12 for task invalid (Data Quality validation failed...; 1935)
[2025-09-03T04:40:15.053+0000] {local_task_job.py:208} INFO - Task exited with return code 1
[2025-09-03T04:40:15.065+0000] {taskinstance.py:2578} INFO - 0 downstream tasks scheduled from follow-on schedule check
